<?xml version="1.0"?>
<sdf version="1.6">
  <world name="robot_demo">
    
    <physics name="1ms" type="ode">
      <max_step_size>0.001</max_step_size>
      <real_time_factor>1.0</real_time_factor>
    </physics>
    
    <scene>
      <ambient>0.4 0.4 0.4 1</ambient>
      <background>0.7 0.7 0.7 1</background>
      <shadows>true</shadows>
    </scene>
    
    <light type="directional" name="sun">
      <cast_shadows>true</cast_shadows>
      <pose>0 0 10 0 0 0</pose>
      <diffuse>1 1 1 1</diffuse>
      <specular>0.5 0.5 0.5 1</specular>
      <direction>-0.5 0.1 -0.9</direction>
    </light>
    
    <!-- Ground -->
    <model name="ground_plane">
      <static>true</static>
      <link name="link">
        <collision name="collision">
          <geometry>
            <plane>
              <normal>0 0 1</normal>
              <size>100 100</size>
            </plane>
          </geometry>
        </collision>
        <visual name="visual">
          <geometry>
            <plane>
              <normal>0 0 1</normal>
              <size>100 100</size>
            </plane>
          </geometry>
          <material>
            <ambient>0.8 0.8 0.8 1</ambient>
            <diffuse>0.8 0.8 0.8 1</diffuse>
            <specular>0 0 0 1</specular>
          </material>
        </visual>
      </link>
    </model>
    
    <!-- Panda-like 6-DOF Robot Arm -->
    <model name="panda_arm">
      <pose>0 0 0 0 0 0</pose>
      <static>false</static>
      
      <!-- Base Link -->
      <link name="base_link">
        <pose>0 0 0 0 0 0</pose>
        <inertial>
          <mass>4.0</mass>
          <inertia>
            <ixx>0.1</ixx>
            <ixy>0</ixy>
            <ixz>0</ixz>
            <iyy>0.1</iyy>
            <iyz>0</iyz>
            <izz>0.1</izz>
          </inertia>
        </inertial>
        <collision name="collision">
          <geometry>
            <cylinder>
              <radius>0.06</radius>
              <length>0.15</length>
            </cylinder>
          </geometry>
        </collision>
        <visual name="visual">
          <geometry>
            <cylinder>
              <radius>0.06</radius>
              <length>0.15</length>
            </cylinder>
          </geometry>
          <material>
            <ambient>0.9 0.9 0.9 1</ambient>
            <diffuse>0.9 0.9 0.9 1</diffuse>
          </material>
        </visual>
      </link>
      
      <!-- Link 1 (Vertical) -->
      <link name="link1">
        <pose>0 0 0.2 0 0 0</pose>
        <inertial>
          <mass>3.0</mass>
          <inertia>
            <ixx>0.05</ixx>
            <iyy>0.05</iyy>
            <izz>0.01</izz>
          </inertia>
        </inertial>
        <collision name="collision">
          <geometry>
            <cylinder>
              <radius>0.05</radius>
              <length>0.2</length>
            </cylinder>
          </geometry>
        </collision>
        <visual name="visual">
          <geometry>
            <cylinder>
              <radius>0.05</radius>
              <length>0.2</length>
            </cylinder>
          </geometry>
          <material>
            <ambient>1 0.5 0 1</ambient>
            <diffuse>1 0.6 0 1</diffuse>
          </material>
        </visual>
      </link>
      
      <!-- Link 2 (Upper Arm) -->
      <link name="link2">
        <pose>0.15 0 0.3 0 1.57 0</pose>
        <inertial>
          <mass>2.5</mass>
          <inertia>
            <ixx>0.04</ixx>
            <iyy>0.04</iyy>
            <izz>0.01</izz>
          </inertia>
        </inertial>
        <collision name="collision">
          <geometry>
            <cylinder>
              <radius>0.04</radius>
              <length>0.3</length>
            </cylinder>
          </geometry>
        </collision>
        <visual name="visual">
          <geometry>
            <cylinder>
              <radius>0.04</radius>
              <length>0.3</length>
            </cylinder>
          </geometry>
          <material>
            <ambient>0.2 0.2 0.2 1</ambient>
            <diffuse>0.3 0.3 0.3 1</diffuse>
          </material>
        </visual>
      </link>
      
      <!-- Link 3 (Forearm Part 1) -->
      <link name="link3">
        <pose>0.3 0 0.25 0 1.57 0</pose>
        <inertial>
          <mass>2.0</mass>
          <inertia>
            <ixx>0.03</ixx>
            <iyy>0.03</iyy>
            <izz>0.01</izz>
          </inertia>
        </inertial>
        <collision name="collision">
          <geometry>
            <cylinder>
              <radius>0.035</radius>
              <length>0.25</length>
            </cylinder>
          </geometry>
        </collision>
        <visual name="visual">
          <geometry>
            <cylinder>
              <radius>0.035</radius>
              <length>0.25</length>
            </cylinder>
          </geometry>
          <material>
            <ambient>1 0.5 0 1</ambient>
            <diffuse>1 0.6 0 1</diffuse>
          </material>
        </visual>
      </link>
      
      <!-- Link 4 (Forearm Part 2) -->
      <link name="link4">
        <pose>0.425 0 0.2 0 1.57 0</pose>
        <inertial>
          <mass>1.5</mass>
          <inertia>
            <ixx>0.02</ixx>
            <iyy>0.02</iyy>
            <izz>0.01</izz>
          </inertia>
        </inertial>
        <collision name="collision">
          <geometry>
            <cylinder>
              <radius>0.03</radius>
              <length>0.2</length>
            </cylinder>
          </geometry>
        </collision>
        <visual name="visual">
          <geometry>
            <cylinder>
              <radius>0.03</radius>
              <length>0.2</length>
            </cylinder>
          </geometry>
          <material>
            <ambient>0.2 0.2 0.2 1</ambient>
            <diffuse>0.3 0.3 0.3 1</diffuse>
          </material>
        </visual>
      </link>
      
      <!-- Gripper/End Effector -->
      <link name="gripper">
        <pose>0.525 0 0.2 0 0 0</pose>
        <inertial>
          <mass>0.5</mass>
          <inertia>
            <ixx>0.001</ixx>
            <iyy>0.001</iyy>
            <izz>0.001</izz>
          </inertia>
        </inertial>
        <collision name="collision">
          <geometry>
            <box>
              <size>0.08 0.08 0.08</size>
            </box>
          </geometry>
        </collision>
        <visual name="visual">
          <geometry>
            <box>
              <size>0.08 0.08 0.08</size>
            </box>
          </geometry>
          <material>
            <ambient>0 0.5 1 1</ambient>
            <diffuse>0 0.6 1 1</diffuse>
          </material>
        </visual>
      </link>
      
      <!-- Joints -->
      <joint name="joint1" type="revolute">
        <parent>base_link</parent>
        <child>link1</child>
        <pose>0 0 -0.1 0 0 0</pose>
        <axis>
          <xyz>0 0 1</xyz>
          <limit>
            <lower>-2.8973</lower>
            <upper>2.8973</upper>
          </limit>
        </axis>
      </joint>
      
      <joint name="joint2" type="revolute">
        <parent>link1</parent>
        <child>link2</child>
        <pose>-0.15 0 0 0 0 0</pose>
        <axis>
          <xyz>0 1 0</xyz>
          <limit>
            <lower>-1.7628</lower>
            <upper>1.7628</upper>
          </limit>
        </axis>
      </joint>
      
      <joint name="joint3" type="revolute">
        <parent>link2</parent>
        <child>link3</child>
        <pose>-0.125 0 0 0 0 0</pose>
        <axis>
          <xyz>0 1 0</xyz>
          <limit>
            <lower>-1.7628</lower>
            <upper>1.7628</upper>
          </limit>
        </axis>
      </joint>
      
      <joint name="joint4" type="revolute">
        <parent>link3</parent>
        <child>link4</child>
        <pose>-0.1 0 0 0 0 0</pose>
        <axis>
          <xyz>0 1 0</xyz>
          <limit>
            <lower>-3.0718</lower>
            <upper>3.0718</upper>
          </limit>
        </axis>
      </joint>
      
      <joint name="joint5" type="fixed">
        <parent>link4</parent>
        <child>gripper</child>
      </joint>
      
    </model>
    
    <!-- Red Cube (Target Object) -->
    <model name="cube">
      <pose>0.5 0 0.525 0 0 0</pose>
      <link name="link">
        <collision name="collision">
          <geometry>
            <box>
              <size>0.05 0.05 0.05</size>
            </box>
          </geometry>
        </collision>
        <visual name="visual">
          <geometry>
            <box>
              <size>0.05 0.05 0.05</size>
            </box>
          </geometry>
          <material>
            <ambient>1 0 0 1</ambient>
            <diffuse>1 0 0 1</diffuse>
          </material>
        </visual>
        <inertial>
          <mass>0.1</mass>
        </inertial>
      </link>
    </model>
    
    <!-- Green Target Marker -->
    <model name="target">
      <pose>0.5 0.3 0.5 0 0 0</pose>
      <static>true</static>
      <link name="link">
        <visual name="visual">
          <geometry>
            <cylinder>
              <radius>0.03</radius>
              <length>0.01</length>
            </cylinder>
          </geometry>
          <material>
            <ambient>0 1 0 1</ambient>
            <diffuse>0 1 0 1</diffuse>
          </material>
        </visual>
      </link>
    </model>
    
  </world>
</sdf>
